<?xml version="1.0" ?>
<!-- =================================================================================== -->
<!-- |    This document was autogenerated by xacro from description.xacro              | -->
<!-- |    EDITING THIS FILE BY HAND IS NOT RECOMMENDED                                 | -->
<!-- =================================================================================== -->
<robot name="plutarco" xmlns:xacro="http://ros.org/wiki/xacro">
  <!-- Included URDF/XACRO Files -->
  <material name="Black">
    <color rgba="0.1 0.1 0.1 1.0"/>
  </material>
  <material name="Blue">
    <color rgba="0.0 0.0 0.8 1.0"/>
  </material>
  <material name="Green">
    <color rgba="0.0 0.8 0.0 1.0"/>
  </material>
  <material name="Grey">
    <color rgba="0.5 0.5 0.5 1.0"/>
  </material>
  <material name="DarkGrey">
    <color rgba="0.3 0.3 0.3 1.0"/>
  </material>
  <material name="Red">
    <color rgba="0.8 0.0 0.0 1.0"/>
  </material>
  <material name="White">
    <color rgba="1.0 1.0 1.0 1.0"/>
  </material>
  <material name="Yellow">
    <color rgba="0.8 0.8 0.0 1.0"/>
  </material>
  <!-- Xacro properties -->
  <!-- Parameterised in part by the values in turtlebot_properties.urdf.xacro -->
  <!-- Included URDF/XACRO Files -->
  <!-- Global properties -->
  <!-- Global properties -->
  <!-- Sprockets params -->
  <!-- Sprockets params -->
  <!-- Asus Xtion params -->
  <!-- Asus Xtion params -->
  <!-- base_link -->
  <link name="base_link">
    <visual>
      <origin rpy="0 0 0" xyz="0 0 0"/>
      <geometry>
        <cylinder length=".001" radius="0.05"/>
      </geometry>
      <material name="Red"/>
    </visual>
  </link>
  <!-- base_link -->
  <!-- Body chassis -->
  <link name="body_bottom_chassis_link">
    <visual>
      <geometry>
        <box size="0.27 0.27 .005"/>
      </geometry>
      <material name="Black"/>
    </visual>
  </link>
  <joint name="Body_bottom" type="fixed">
    <axis xyz="0 0 1"/>
    <parent link="base_link"/>
    <child link="body_bottom_chassis_link"/>
    <origin rpy="0 0 0" xyz="0 0 0.057625"/>
    <joint_properties damping="0.0" friction="0.0"/>
  </joint>
  <link name="body_top_chassis_link">
    <visual>
      <geometry>
        <box size="0.13 0.27 .055"/>
      </geometry>
      <material name="Black"/>
    </visual>
  </link>
  <joint name="Body_top" type="fixed">
    <axis xyz="0 0 1"/>
    <parent link="base_link"/>
    <child link="body_top_chassis_link"/>
    <origin rpy="0 0 0" xyz="-0.035 0 0.085125"/>
    <joint_properties damping="0.0" friction="0.0"/>
  </joint>
  <link name="asus_support_link">
    <visual>
      <geometry>
        <box size="0.015 0.015 .015"/>
      </geometry>
      <material name="Black"/>
    </visual>
  </link>
  <joint name="Asus_support" type="fixed">
    <axis xyz="0 0 1"/>
    <parent link="base_link"/>
    <child link="asus_support_link"/>
    <origin rpy="0 0 0" xyz="0.07775 0 0.1575"/>
    <joint_properties damping="0.0" friction="0.0"/>
  </joint>
  <!-- Body chassis -->
  <!-- Jetson chassis -->
  <link name="jetson_chassis_link">
    <visual>
      <geometry>
        <box size="0.13 0.15 .095"/>
      </geometry>
      <material name="Black"/>
    </visual>
  </link>
  <joint name="Jetson" type="fixed">
    <axis xyz="0 0 1"/>
    <parent link="base_link"/>
    <child link="jetson_chassis_link"/>
    <origin rpy="0 0 0" xyz="0.035 0 0.107625"/>
    <joint_properties damping="0.0" friction="0.0"/>
  </joint>
  <!-- Jetson chassis -->
  <!-- Asus Xtion Pro Live -->
  <joint name="rgbd_camera_rgb_joint" type="fixed">
    <origin rpy="0 0 0" xyz="0.095 0.022 0.1825"/>
    <parent link="base_link"/>
    <child link="rgbd_camera_rgb_frame"/>
  </joint>
  <link name="rgbd_camera_rgb_frame"/>
  <joint name="camera_rgb_optical_joint" type="fixed">
    <origin rpy="-1.570795 0 -1.570795" xyz="0 0 0"/>
    <parent link="rgbd_camera_rgb_frame"/>
    <child link="rgbd_camera_rgb_optical_frame"/>
  </joint>
  <link name="rgbd_camera_rgb_optical_frame"/>
  <joint name="rgbd_camera_joint" type="fixed">
    <origin rpy="0 0 0" xyz="0 -0.022 0"/>
    <parent link="rgbd_camera_rgb_frame"/>
    <child link="rgbd_camera_link"/>
  </joint>
  <link name="rgbd_camera_link">
    <visual>
      <origin rpy="-1.570795 -3.14159 -1.570795" xyz="-0.01 0 0"/>
      <geometry>
        <mesh filename="package://ros_plutarco_robot/meshes/sensors/asus_xtion_pro_live.dae" scale="0.001 0.001 0.001"/>
      </geometry>
    </visual>
    <collision>
      <origin rpy="0 0 0" xyz="0.0 0.0 0.0"/>
      <geometry>
        <box size="0.0730 0.2760 0.0720"/>
      </geometry>
    </collision>
    <inertial>
      <mass value="0.170"/>
      <origin xyz="0 0 0"/>
      <inertia ixx="0.001152600" ixy="0.0" ixz="0.0" iyy="0.000148934" iyz="0.0" izz="0.001154654"/>
    </inertial>
  </link>
  <joint name="rgbd_camera_depth_joint" type="fixed">
    <origin rpy="0 0 0" xyz="0 0.027 0"/>
    <parent link="rgbd_camera_rgb_frame"/>
    <child link="rgbd_camera_depth_frame"/>
  </joint>
  <link name="rgbd_camera_depth_frame"/>
  <joint name="camera_depth_optical_joint" type="fixed">
    <origin rpy="-1.570795 0 -1.570795" xyz="0 0 0"/>
    <parent link="rgbd_camera_depth_frame"/>
    <child link="rgbd_camera_depth_optical_frame"/>
  </joint>
  <link name="rgbd_camera_depth_optical_frame"/>
  <!-- Asus Xtion Pro Live -->
  <!-- Active Sprockets -->
  <link name="Left_wheel">
    <visual>
      <geometry>
        <cylinder length="0.034925" radius="0.034925"/>
      </geometry>
      <material name="DarkGrey"/>
    </visual>
  </link>
  <joint name="Left" type="continuous">
    <parent link="base_link"/>
    <child link="Left_wheel"/>
    <limit effort="100" velocity="100"/>
    <joint_properties damping="0.0" friction="0.0"/>
    <origin rpy="-1.570795 0 0" xyz="-0.055 0.16 0.15"/>
    <axis xyz="0 0 1"/>
  </joint>
  <link name="Right_wheel">
    <visual>
      <geometry>
        <cylinder length="0.034925" radius="0.034925"/>
      </geometry>
      <material name="DarkGrey"/>
    </visual>
  </link>
  <joint name="Right" type="continuous">
    <parent link="base_link"/>
    <child link="Right_wheel"/>
    <limit effort="100" velocity="100"/>
    <joint_properties damping="0.0" friction="0.0"/>
    <origin rpy="-1.570795 0 0" xyz="-0.055 -0.16 0.15"/>
    <axis xyz="0 0 1"/>
  </joint>
  <link name="Left_motor_link">
    <visual>
      <geometry>
        <cylinder length="0.09" radius="0.02"/>
      </geometry>
      <material name="Grey"/>
    </visual>
  </link>
  <joint name="Left_motor" type="fixed">
    <parent link="base_link"/>
    <child link="Left_motor_link"/>
    <limit effort="100" velocity="100"/>
    <joint_properties damping="0.0" friction="0.0"/>
    <origin rpy="-1.570795 0 0" xyz="-0.055 0.09015 0.15"/>
    <axis xyz="0 0 1"/>
  </joint>
  <link name="Right_motor_link">
    <visual>
      <geometry>
        <cylinder length="0.09" radius="0.02"/>
      </geometry>
      <material name="Grey"/>
    </visual>
  </link>
  <joint name="Right_motor" type="fixed">
    <parent link="base_link"/>
    <child link="Right_motor_link"/>
    <limit effort="100" velocity="100"/>
    <joint_properties damping="0.0" friction="0.0"/>
    <origin rpy="-1.570795 0 0" xyz="-0.055 -0.09015 0.15"/>
    <axis xyz="0 0 1"/>
  </joint>
  <!-- Active Sprockets -->
  <!-- Passive Sprockets -->
  <link name="spr_bfl">
    <visual>
      <geometry>
        <cylinder length="0.047625" radius="0.047625"/>
      </geometry>
      <material name="DarkGrey"/>
    </visual>
  </link>
  <joint name="Sprocket_bfl" type="continuous">
    <parent link="base_link"/>
    <child link="spr_bfl"/>
    <limit effort="100" velocity="100"/>
    <joint_properties damping="0.0" friction="0.0"/>
    <origin rpy="-1.570795 0 0" xyz="0.135 0.165 0.047625"/>
    <axis rpy="0 0 0" xyz="0 0 1"/>
    <!-- Passive sprocket rotate automatically according to the status of the active one -->
    <mimic joint="Left" multiplier="0.733333333333" offset="0"/>
  </joint>
  <link name="spr_brl">
    <visual>
      <geometry>
        <cylinder length="0.047625" radius="0.047625"/>
      </geometry>
      <material name="DarkGrey"/>
    </visual>
  </link>
  <joint name="Sprocket_brl" type="continuous">
    <parent link="base_link"/>
    <child link="spr_brl"/>
    <limit effort="100" velocity="100"/>
    <joint_properties damping="0.0" friction="0.0"/>
    <origin rpy="-1.570795 0 0" xyz="-0.135 0.165 0.047625"/>
    <axis rpy="0 0 0" xyz="0 0 1"/>
    <!-- Passive sprocket rotate automatically according to the status of the active one -->
    <mimic joint="Left" multiplier="0.733333333333" offset="0"/>
  </joint>
  <link name="spr_bfr">
    <visual>
      <geometry>
        <cylinder length="0.047625" radius="0.047625"/>
      </geometry>
      <material name="DarkGrey"/>
    </visual>
  </link>
  <joint name="Sprocket_bfr" type="continuous">
    <parent link="base_link"/>
    <child link="spr_bfr"/>
    <limit effort="100" velocity="100"/>
    <joint_properties damping="0.0" friction="0.0"/>
    <origin rpy="-1.570795 0 0" xyz="0.135 -0.165 0.047625"/>
    <axis rpy="0 0 0" xyz="0 0 1"/>
    <!-- Passive sprocket rotate automatically according to the status of the active one -->
    <mimic joint="Right" multiplier="0.733333333333" offset="0"/>
  </joint>
  <link name="spr_brr">
    <visual>
      <geometry>
        <cylinder length="0.047625" radius="0.047625"/>
      </geometry>
      <material name="DarkGrey"/>
    </visual>
  </link>
  <joint name="Sprocket_brr" type="continuous">
    <parent link="base_link"/>
    <child link="spr_brr"/>
    <limit effort="100" velocity="100"/>
    <joint_properties damping="0.0" friction="0.0"/>
    <origin rpy="-1.570795 0 0" xyz="-0.135 -0.165 0.047625"/>
    <axis rpy="0 0 0" xyz="0 0 1"/>
    <!-- Passive sprocket rotate automatically according to the status of the active one -->
    <mimic joint="Right" multiplier="0.733333333333" offset="0"/>
  </joint>
  <!-- Passive Sprockets -->
  <xacro:plutarco_robot/>
</robot>
